<sdf version='1.5'>
  <model name='snake'>
  	
    <link name='base_link'>
      <pose>0 0 0 0 -0 0</pose>
      <inertial>
        <pose>0 0 0 0 -0 0</pose>
        <mass>1.031</mass>
        <inertia>
          <ixx>0.00357413</ixx>
          <ixy>0</ixy>
          <ixz>0</ixz>
          <iyy>0.00508627</iyy>
          <iyz>0</iyz>
          <izz>0.00838547</izz>
        </inertia>
      </inertial>
      <collision name='base_link_collision'>
        <pose>0 0 0 0 -0 0</pose>
        <geometry>
          <cylinder>
            <length>0.15</length>
            <radius>0.05</radius>
          </cylinder>
        </geometry>
      </collision>
      <visual name='base_link_visual'>
        <pose>0 0 0 0 -0 0</pose>
        <geometry>
          <cylinder>
            <length>0.15</length>
            <radius>0.05</radius>
          </cylinder>
        </geometry>
        <material>
          <script>
            <uri>file://media/materials/scripts/gazebo.material</uri>
            <name>Gazebo/Red</name>
          </script>
        </material>
      </visual>
    </link>
    
    
    <link name='aux_body_link'>
      <pose>0 0 0.1 0 -0 0</pose>
      <inertial>
        <pose>0 0 0 0 -0 0</pose>
        <mass>0.02</mass>
        <inertia>
          <ixx>8e-06</ixx>
          <ixy>0</ixy>
          <ixz>0</ixz>
          <iyy>8e-06</iyy>
          <iyz>0</iyz>
          <izz>6.66667e-07</izz>
        </inertia>
      </inertial>
      <collision name='aux_body_link_collision'>
        <pose>0 0 0 0 -0 0</pose>
        <geometry>
          <cylinder>
            <length>0.05</length>
            <radius>0.05</radius>
          </cylinder>
        </geometry>
      </collision>
      <visual name='aux_body_link_visual'>
        <pose>0 0 0 0 -0 0</pose>
        <geometry>
          <cylinder>
            <length>0.05</length>
            <radius>0.05</radius>
          </cylinder>
        </geometry>
        <material>
          <script>
            <uri>file://media/materials/scripts/gazebo.material</uri>
            <name>Gazebo/Green</name>
          </script>
        </material>
      </visual>
    </link>
    
    
    <joint name='body_leg_0' type='revolute'>
        <pose>0 0 -0.025 0 0 0</pose>
      <child>aux_body_link</child>
      <parent>base_link</parent>
      <axis>
        <xyz>1 0 0</xyz>
        <limit>
          <lower>-0.785398</lower>
          <upper>0.785398</upper>
          <effort>20</effort>
          <velocity>2</velocity>
        </limit>
      </axis>
    </joint>
    
    <!-- The Pose is absolute is where the  axis will be placed-->
    <link name='body_link'>
      <pose>0 0 0.2 0 -0 0</pose>
      <inertial>
        <pose>0 0 0 0 -0 0</pose>
        <mass>0.02</mass>
        <inertia>
          <ixx>8e-06</ixx>
          <ixy>0</ixy>
          <ixz>0</ixz>
          <iyy>8e-06</iyy>
          <iyz>0</iyz>
          <izz>6.66667e-07</izz>
        </inertia>
      </inertial>
      <collision name='body_link_collision'>
        <pose>0 0 0 0 -0 0</pose>
        <geometry>
          <cylinder>
            <length>0.15</length>
            <radius>0.05</radius>
          </cylinder>
        </geometry>
      </collision>
      <visual name='body_link_visual'>
        <pose>0 0 0 0 -0 0</pose>
        <geometry>
          <cylinder>
            <length>0.15</length>
            <radius>0.05</radius>
          </cylinder>
        </geometry>
        <material>
          <script>
            <uri>file://media/materials/scripts/gazebo.material</uri>
            <name>Gazebo/Blue</name>
          </script>
        </material>
      </visual>
    </link>
    
    <!-- Its reffered to the child frame -->
    <joint name='body_leg_1' type='revolute'>
        <pose>0 0 -0.075 0 0 0</pose>
      <child>body_link</child>
      <parent>aux_body_link</parent>
      <axis>
        <xyz>0 1 0</xyz>
        <limit>
          <lower>-0.785398</lower>
          <upper>0.785398</upper>
          <effort>20</effort>
          <velocity>2</velocity>
        </limit>
      </axis>
    </joint>
    
    

  </model>
</sdf>