<?xml version="1.0"?>
<robot xmlns:xacro="http://www.ros.org/wiki/xacro" name="snake">
    
    <gazebo>
        <plugin name="gazebo_ros_control" filename="libgazebo_ros_control.so">
            <robotNamespace>/snake</robotNamespace>
        </plugin>
    </gazebo>
    <!-- MACROS -->
    
    
    <xacro:property name="NumberOfElements" value="$(arg prefix)" />
    
    <xacro:macro name="loop" params="links_qty">
        
        <xacro:if value="${links_qty > 0}">
            <xacro:body_link base_name="snake_body_${links_qty-1}" parent_name="snake_body_${links_qty}" colour="Green"/>
            
            <xacro:if value="${links_qty}">
                <xacro:loop links_qty="${links_qty-1}" />
            </xacro:if>
        </xacro:if>
    </xacro:macro>
    
    <xacro:loop links_qty="${NumberOfElements}" />
    


    
    
    <xacro:macro name="body_link" params="base_name parent_name colour">
        
        <link name="${base_name}_aux">
            <inertial>
                <origin xyz="0 0 0.025" rpy="0 0 0"/>
                <mass value="0.1" />
                <inertia ixx="0.00025" ixy="0.0" ixz="0.0" iyy="0.00025" iyz="0.0" izz="0.000125"/>
            </inertial>
            <collision>
                <origin xyz="0 0 0.025" rpy="0 0 0"/>
                <geometry>
                    <cylinder radius="0.05" length="0.05"/>
                </geometry>
            </collision>
            <visual>
                <origin xyz="0 0 0.025" rpy="0 0 0"/>
                <geometry>
                    <cylinder radius="0.05" length="0.05"/>
                </geometry>
            </visual>
    	</link>
    	
    	<gazebo reference="${base_name}_aux">
            <kp>1000000000.0</kp>
            <kd>1000000000.0</kd>
            <mu1>10.0</mu1>
            <mu2>10.0</mu2>
            <material>Gazebo/Black</material>
            <self_collide>1</self_collide>
        </gazebo>
    	
    	
        <link name="${base_name}">
     	    <inertial>
                <origin xyz="0 0 0.075" rpy="0 0 0"/>
                <mass value="0.1" />
                <inertia ixx="0.00025" ixy="0.0" ixz="0.0" iyy="0.00025" iyz="0.0" izz="0.000125"/>
            </inertial>
            <collision>
                <origin xyz="0 0 0.075" rpy="0 0 0"/>
                <geometry>
                    <cylinder radius="0.05" length="0.15"/>
                </geometry>
            </collision>
            <visual>
                <origin xyz="0 0 0.075" rpy="0 0 0"/>
                <geometry>
                    <cylinder radius="0.05" length="0.15"/>
                </geometry>
            </visual>
    	</link>
    	
    	<gazebo reference="${base_name}">
            <kp>1000000000.0</kp>
            <kd>1000000000.0</kd>
            <mu1>10.0</mu1>
            <mu2>10.0</mu2>
            <material>Gazebo/${colour}</material>
            <self_collide>1</self_collide>
        </gazebo>
        
        <!-- We add to the Origin displacement a margin for flex due to self colisions for parent_name and base_name-->
        <joint name="${base_name}_aux_joint" type="revolute">
            <parent link="${parent_name}"/>
        	<child link="${base_name}_aux"/>
            <origin xyz="0 0 0.15" rpy="0 0 0"/>
            <limit lower="-1.5708" upper="1.5708" effort="100.0" velocity="0.5"/>
            <axis xyz="1 0 0"/>
    	</joint>
    	
        <joint name="${base_name}_joint" type="revolute">
    	    <parent link="${base_name}_aux"/>
        	<child link="${base_name}"/>
            <origin xyz="0 0 0.05" rpy="0 0 0"/>
            <limit lower="-1.5708" upper="1.5708" effort="100.0" velocity="0.5"/>
            <axis xyz="0 1 0"/>
    	</joint>
    	
    	
	    <transmission name="tran${base_name}_aux">
            <type>transmission_interface/SimpleTransmission</type>
            <joint name="${base_name}_aux_joint">
                <hardwareInterface>hardware_interface/EffortJointInterface</hardwareInterface>
            </joint>
            <actuator name="motor${base_name}_aux">
                <hardwareInterface>hardware_interface/EffortJointInterface</hardwareInterface>
                <mechanicalReduction>1</mechanicalReduction>
            </actuator>
        </transmission>
        
        <transmission name="tran${base_name}">
            <type>transmission_interface/SimpleTransmission</type>
            <joint name="${base_name}_joint">
                <hardwareInterface>hardware_interface/EffortJointInterface</hardwareInterface>
            </joint>
            <actuator name="motor${base_name}">
                <hardwareInterface>hardware_interface/EffortJointInterface</hardwareInterface>
                <mechanicalReduction>1</mechanicalReduction>
            </actuator>
        </transmission>
    	
    </xacro:macro>
	<!-- * * * Link Definitions * * * -->
	
	
	<link name="snake_body_${NumberOfElements}">
     	    <inertial>
                <origin xyz="0 0 0.075" rpy="0 0 0"/>
                <mass value="0.1" />
                <inertia ixx="0.00025" ixy="0.0" ixz="0.0" iyy="0.00025" iyz="0.0" izz="0.000125"/>
            </inertial>
            <collision>
                <origin xyz="0 0 0.075" rpy="0 0 0"/>
                <geometry>
                    <cylinder radius="0.05" length="0.15"/>
                </geometry>
            </collision>
            <visual>
                <origin xyz="0 0 0.075" rpy="0 0 0"/>
                <geometry>
                    <cylinder radius="0.05" length="0.15"/>
                </geometry>
            </visual>
	</link>


    <gazebo reference="snake_body_${NumberOfElements}">
        <kp>100000000000000.0</kp>
        <kd>100000000000000.0</kd>
        <mu1>10.0</mu1>
        <mu2>10.0</mu2>
        <material>Gazebo/Red</material>
        <self_collide>1</self_collide>
    </gazebo>

</robot>